Workbook
Name \0: #REF!
Name \a: #REF!
Name \z: #REF!
Name a: #REF!
Name aa: #REF!
Name aaa: aaa
Name abc: abc
Name BT: #REF!
Name CCFF1: #REF!
Name CCFF1000: #REF!
Name CCFF1001: #REF!
Name CCFF1002: #REF!
Name CCFF1003: #REF!
Name CCFF1004: #REF!
Name CCFF1005: #REF!
Name CCFF1006: #REF!
Name CCFF1007: #REF!
Name CCFF1016: #REF!
Name CCFF1017: #REF!
Name CCFF1018: #REF!
Name CCFF1019: #REF!
Name CCFF1020: #REF!
Name CCFF1021: #REF!
Name CCFF1022: #REF!
Name CCFF1023: #REF!
Name CCFF1024: #REF!
Name CCFF1029: #REF!
Name CCFF1030: #REF!
Name CCFF1031: #REF!
Name CCFF1032: #REF!
Name CCFF1033: #REF!
Name CCFF1034: #REF!
Name CCFF1035: #REF!
Name CCFF1036: #REF!
Name CCFF1037: #REF!
Name CCFF1048: #REF!
Name CCFF1049: #REF!
Name CCFF1050: #REF!
Name CCFF1051: #REF!
Name CCFF1052: #REF!
Name CCFF1053: #REF!
Name CCFF1054: #REF!
Name CCFF1055: #REF!
Name CCFF1056: #REF!
Name CCFF1065: #REF!
Name CCFF1066: #REF!
Name CCFF1067: #REF!
Name CCFF1068: #REF!
Name CCFF1069: #REF!
Name CCFF1070: #REF!
Name CCFF1071: #REF!
Name CCFF1072: #REF!
Name CCFF1073: #REF!
Name CCFF134: #REF!
Name CCFF135: #REF!
Name CCFF136: #REF!
Name CCFF137: #REF!
Name CCFF138: #REF!
Name CCFF139: #REF!
Name CCFF140: #REF!

Sheet 1-汇总表
A1: 资产评估结果汇总表
A2: 评估基准日：2018年10月23日
F3: 表1
A4: 被执行人：俞海敏 | F4: 金额单位：人民币万元
A5: 项 目 | C5: 账面价值 | D5: 评估价值 | E5: 增值额 | F5: 增值率％
C6: A | D6: B | E6: C=B-A | F6: D=C/A×100
A7: 1 | B7: 流动资产 | C7: 0 | D7: 0.4 | E7: =D7-C7 -> 0.4 | F7: =IF(C7=0,"",E7/C7*100)
A8: 2 | B8: 非流动资产 | C8: =ROUND('4-非流动资产汇总'!C26/10000,2) -> 0 | D8: =ROUND('4-非流动资产汇总'!D26/10000,2) -> 229.44 | E8: =D8-C8 -> 229.44 | F8: =IF(C8=0,"",E8/C8*100)
A9: 3 | B9: 其中：可供出售金融资产 | C9: =ROUND('4-非流动资产汇总'!C6/10000,2) -> 0 | D9: =ROUND('4-非流动资产汇总'!D6/10000,2) -> 0 | E9: =D9-C9 -> 0 | F9: =IF(C9=0,"",E9/C9*100)
A10: 4 | B10: 持有至到期投资 | C10: =ROUND('4-非流动资产汇总'!C7/10000,2) -> 0 | D10: =ROUND('4-非流动资产汇总'!D7/10000,2) -> 0 | E10: =D10-C10 -> 0 | F10: =IF(C10=0,"",E10/C10*100)
A11: 5 | B11: 长期应收款 | C11: =ROUND('4-非流动资产汇总'!C8/10000,2) -> 0 | D11: =ROUND('4-非流动资产汇总'!D8/10000,2) -> 0 | E11: =D11-C11 -> 0 | F11: =IF(C11=0,"",E11/C11*100)
A12: 6 | B12: 长期股权投资 | C12: =ROUND('4-非流动资产汇总'!C9/10000,2) -> 0 | D12: =ROUND('4-非流动资产汇总'!D9/10000,2) -> 0 | E12: =D12-C12 -> 0 | F12: =IF(C12=0,"",E12/C12*100)
A13: 7 | B13: 投资性房地产 | C13: =ROUND('4-非流动资产汇总'!C10/10000,2) -> 0 | D13: =ROUND('4-非流动资产汇总'!D10/10000,2) -> 0 | E13: =D13-C13 -> 0 | F13: =IF(C13=0,"",E13/C13*100)
A14: 8 | B14: 固定资产 | C14: =ROUND('4-非流动资产汇总'!C11/10000,2) -> 0 | D14: =ROUND('4-非流动资产汇总'!D11/10000,2) -> 229.44 | E14: =D14-C14 -> 229.44 | F14: =IF(C14=0,"",E14/C14*100)
A15: 9 | B15: 在建工程 | C15: =ROUND('4-非流动资产汇总'!C12/10000,2) -> 0 | D15: =ROUND('4-非流动资产汇总'!D12/10000,2) -> 0 | E15: =D15-C15 -> 0 | F15: =IF(C15=0,"",E15/C15*100)
A16: 10 | B16: 工程物资 | C16: =ROUND('4-非流动资产汇总'!C13/10000,2) -> 0 | D16: =ROUND('4-非流动资产汇总'!D13/10000,2) -> 0 | E16: =D16-C16 -> 0 | F16: =IF(C16=0,"",E16/C16*100)
A17: 11 | B17: 固定资产清理 | C17: =ROUND('4-非流动资产汇总'!C14/10000,2) -> 0 | D17: =ROUND('4-非流动资产汇总'!D14/10000,2) -> 0 | E17: =D17-C17 -> 0 | F17: =IF(C17=0,"",E17/C17*100)
A18: 12 | B18: 生产性生物资产 | C18: =ROUND('4-非流动资产汇总'!C15/10000,2) -> 0 | D18: =ROUND('4-非流动资产汇总'!D15/10000,2) -> 0 | E18: =D18-C18 -> 0 | F18: =IF(C18=0,"",E18/C18*100)
A19: 13 | B19: 油气资产 | C19: =ROUND('4-非流动资产汇总'!C16/10000,2) -> 0 | D19: =ROUND('4-非流动资产汇总'!D16/10000,2) -> 0 | E19: =D19-C19 -> 0 | F19: =IF(C19=0,"",E19/C19*100)
A20: 14 | B20: 无形资产 | C20: =ROUND('4-非流动资产汇总'!C17/10000,2) -> 0 | D20: =ROUND('4-非流动资产汇总'!D17/10000,2) -> 0 | E20: =D20-C20 -> 0 | F20: =IF(C20=0,"",E20/C20*100)
... A25: 19 | B25: 其他非流动资产 | C25: =ROUND('4-非流动资产汇总'!C22/10000,2) -> 0 | D25: =ROUND('4-非流动资产汇总'!D22/10000,2) -> 0 | E25: =D25-C25 -> 0 | F25: =IF(C25=0,"",E25/C25*100)
A26: 20 | B26: 资产总计 | C26: =SUM(C7:C8) -> 0 | D26: =SUM(D7:D8) -> 229.84 | E26: =D26-C26 -> 229.84 | F26: =IF(C26=0,"",E26/C26*100)
A27: 21 | B27: 流动负债 | C27: 0 | D27: 0 | E27: =D27-C27 -> 0 | F27: =IF(C27=0,"",E27/C27*100)
A28: 22 | B28: 非流动负债 | C28: 0 | D28: 0 | E28: =D28-C28 -> 0 | F28: =IF(C28=0,"",E28/C28*100)
A29: 23 | B29: 负债合计 | C29: =SUM(C27:C28) -> 0 | D29: =SUM(D27:D28) -> 0 | E29: =D29-C29 -> 0 | F29: =IF(C29=0,"",E29/C29*100)
A30: 24 | B30: 净资产（所有者权益） | C30: =C26-C29 -> 0 | D30: =D26-D29 -> 229.84 | E30: =D30-C30 -> 229.84 | F30: =IF(C30=0,"",E30/C30*100)
F31: 评估机构：天源资产评估有限公司
C32: =IF((C26-C29)=C30,"","不平") | D32: =IF((D26-D29)=D30,"","不平")

Sheet 2-分类汇总
A1: 资产评估结果分类汇总表
A2: 评估基准日：2018年10月23日
F3: 表2
A4: 被评估单位：俞海敏 | F4: 金额单位：人民币元
A5: 序号 | B5: 科目名称 | C5: 账面价值 | D5: 评估价值 | E5: 增值额 | F5: 增值率% | G5: 账面差异
A6: 1 | B6: 一、流动资产合计 | C6: =SUM(C7:C17) -> 0 | D6: =SUM(D7:D17) -> 3970 | E6: =D6-C6 -> 3970 | F6: =IF(C6=0,"",E6/C6*100)
A7: 2 | B7: 货币资金 | C7: 0 | D7: 0 | E7: =D7-C7 -> 0 | F7: =IF(C7=0,"",E7/C7*100) | G7: 0
A8: 3 | B8: 交易性金融资产 | C8: 0 | D8: 0 | E8: =D8-C8 -> 0 | F8: =IF(C8=0,"",E8/C8*100) | G8: 0
A9: 4 | B9: 应收票据 | C9: 0 | D9: 0 | E9: =D9-C9 -> 0 | F9: =IF(C9=0,"",E9/C9*100) | G9: 0
A10: 5 | B10: 应收账款 | C10: 0 | D10: 0 | E10: =D10-C10 -> 0 | F10: =IF(C10=0,"",E10/C10*100) | G10: 0
A11: 6 | B11: 预付款项 | C11: 0 | D11: 0 | E11: =D11-C11 -> 0 | F11: =IF(C11=0,"",E11/C11*100) | G11: 0
A12: 7 | B12: 应收利息 | C12: 0 | D12: 0 | E12: =D12-C12 -> 0 | F12: =IF(C12=0,"",E12/C12*100) | G12: 0
A13: 8 | B13: 应收股利 | C13: 0 | D13: 0 | E13: =D13-C13 -> 0 | F13: =IF(C13=0,"",E13/C13*100) | G13: 0
A14: 9 | B14: 其他应收款 | C14: 0 | D14: 0 | E14: =D14-C14 -> 0 | F14: =IF(C14=0,"",E14/C14*100) | G14: 0
A15: 10 | B15: 存货 | C15: 0 | D15: 3970 | E15: =D15-C15 -> 3970 | F15: =IF(C15=0,"",E15/C15*100) | G15: 0
A16: 11 | B16: 一年内到期的非流动资产 | C16: 0 | D16: 0 | E16: =D16-C16 -> 0 | F16: =IF(C16=0,"",E16/C16*100) | G16: 0
A17: 12 | B17: 其他流动资产 | C17: 0 | D17: 0 | E17: =D17-C17 -> 0 | F17: =IF(C17=0,"",E17/C17*100) | G17: 0
A18: 13 | B18: 二、非流动资产合计 | C18: =SUM(C19:C35) -> 0 | D18: =SUM(D19:D35) -> 2294400 | E18: =D18-C18 -> 2294400 | F18: =IF(C18=0,"",E18/C18*100)
A19: 14 | B19: 可供出售金融资产 | C19: ='4-非流动资产汇总'!C6 -> 0 | D19: ='4-非流动资产汇总'!D6 -> 0 | E19: =D19-C19 -> 0 | F19: =IF(C19=0,"",E19/C19*100) | G19: =C19-'4-非流动资产汇总'!C6 -> 0
A20: 15 | B20: 持有至到期投资 | C20: ='4-非流动资产汇总'!C7 -> 0 | D20: ='4-非流动资产汇总'!D7 -> 0 | E20: =D20-C20 -> 0 | F20: =IF(C20=0,"",E20/C20*100) | G20: =C20-'4-非流动资产汇总'!C7 -> 0
A21: 16 | B21: 长期应收款 | C21: ='4-非流动资产汇总'!C8 -> 0 | D21: ='4-非流动资产汇总'!D8 -> 0 | E21: =D21-C21 -> 0 | F21: =IF(C21=0,"",E21/C21*100) | G21: =C21-'4-非流动资产汇总'!C8 -> 0
A22: 17 | B22: 长期股权投资 | C22: ='4-非流动资产汇总'!C9 -> 0 | D22: ='4-非流动资产汇总'!D9 -> 0 | E22: =D22-C22 -> 0 | F22: =IF(C22=0,"",E22/C22*100) | G22: =C22-'4-非流动资产汇总'!C9 -> 0
A23: 18 | B23: 投资性房地产 | C23: ='4-非流动资产汇总'!C10 -> 0 | D23: ='4-非流动资产汇总'!D10 -> 0 | E23: =D23-C23 -> 0 | F23: =IF(C23=0,"",E23/C23*100) | G23: =C23-'4-非流动资产汇总'!C10 -> 0
A24: 19 | B24: 固定资产 | C24: ='4-非流动资产汇总'!C11 -> 0 | D24: ='4-非流动资产汇总'!D11 -> 2294400 | E24: =D24-C24 -> 2294400 | F24: =IF(C24=0,"",E24/C24*100) | G24: =C24-'4-非流动资产汇总'!C11 -> 0
A25: 20 | B25: 在建工程 | C25: ='4-非流动资产汇总'!C12 -> 0 | D25: ='4-非流动资产汇总'!D12 -> 0 | E25: =D25-C25 -> 0 | F25: =IF(C25=0,"",E25/C25*100) | G25: =C25-'4-非流动资产汇总'!C12 -> 0
A26: 21 | B26: 工程物资 | C26: ='4-非流动资产汇总'!C13 -> 0 | D26: ='4-非流动资产汇总'!D13 -> 0 | E26: =D26-C26 -> 0 | F26: =IF(C26=0,"",E26/C26*100) | G26: =C26-'4-非流动资产汇总'!C13 -> 0
A27: 22 | B27: 固定资产清理 | C27: ='4-非流动资产汇总'!C14 -> 0 | D27: ='4-非流动资产汇总'!D14 -> 0 | E27: =D27-C27 -> 0 | F27: =IF(C27=0,"",E27/C27*100) | G27: =C27-'4-非流动资产汇总'!C14 -> 0
A28: 23 | B28: 生产性生物资产 | C28: ='4-非流动资产汇总'!C15 -> 0 | D28: ='4-非流动资产汇总'!D15 -> 0 | E28: =D28-C28 -> 0 | F28: =IF(C28=0,"",E28/C28*100) | G28: =C28-'4-非流动资产汇总'!C15 -> 0
A29: 24 | B29: 油气资产 | C29: ='4-非流动资产汇总'!C16 -> 0 | D29: ='4-非流动资产汇总'!D16 -> 0 | E29: =D29-C29 -> 0 | F29: =IF(C29=0,"",E29/C29*100) | G29: =C29-'4-非流动资产汇总'!C16 -> 0
A30: 25 | B30: 无形资产 | C30: ='4-非流动资产汇总'!C17 -> 0 | D30: ='4-非流动资产汇总'!D17 -> 0 | E30: =D30-C30 -> 0 | F30: =IF(C30=0,"",E30/C30*100) | G30: =C30-'4-非流动资产汇总'!C17 -> 0
... A35: 30 | B35: 其他非流动资产 | C35: ='4-非流动资产汇总'!C22 -> 0 | D35: ='4-非流动资产汇总'!D22 -> 0 | E35: =D35-C35 -> 0 | F35: =IF(C35=0,"",E35/C35*100) | G35: =C35-'4-非流动资产汇总'!C22 -> 0
A36: 31 | B36: 三、资产总计 | C36: =C6+C18 -> 0 | D36: =D6+D18 -> 2298370 | E36: =D36-C36 -> 2298370 | F36: =IF(C36=0,"",E36/C36*100)
A37: 32 | B37: 四、流动负债合计 | C37: =SUM(C38:C49) -> 0 | D37: =SUM(D38:D49) -> 0 | E37: =D37-C37 -> 0 | F37: =IF(C37=0,"",E37/C37*100)
A38: 33 | B38: 短期借款 | C38: 0 | D38: 0 | E38: =D38-C38 -> 0 | F38: =IF(C38=0,"",E38/C38*100) | G38: 0
A39: 34 | B39: 交易性金融负债 | C39: 0 | D39: 0 | E39: =D39-C39 -> 0 | F39: =IF(C39=0,"",E39/C39*100) | G39: 0
A40: 35 | B40: 应付票据 | C40: 0 | D40: 0 | E40: =D40-C40 -> 0 | F40: =IF(C40=0,"",E40/C40*100) | G40: 0
A41: 36 | B41: 应付账款 | C41: 0 | D41: 0 | E41: =D41-C41 -> 0 | F41: =IF(C41=0,"",E41/C41*100) | G41: 0
A42: 37 | B42: 预收款项 | C42: 0 | D42: 0 | E42: =D42-C42 -> 0 | F42: =IF(C42=0,"",E42/C42*100) | G42: 0
A43: 38 | B43: 应付职工薪酬 | C43: 0 | D43: 0 | E43: =D43-C43 -> 0 | F43: =IF(C43=0,"",E43/C43*100) | G43: 0
A44: 39 | B44: 应交税费 | C44: 0 | D44: 0 | E44: =D44-C44 -> 0 | F44: =IF(C44=0,"",E44/C44*100) | G44: 0
...

Sheet 3-9存货汇总
A1: 存货评估汇总表
A2: 评估基准日：2018年10月23日
F3: 表3-9
A4: 被执行人：俞海敏 | F4: 金额单位：人民币元
A5: 编号 | B5: 科目名称 | C5: 账面价值 | D5: 评估价值 | E5: 增值额 | F5: 增值率%
A6: 3-9-1 | B6: 材料采购（在途物资） | C6: 0 | D6: 0 | E6: =D6-C6 -> 0 | F6: =IF(C6=0,"",E6/C6*100)
A7: 3-9-2 | B7: 原材料 | C7: ='3-9-2原材料'!G26 -> 0 | D7: ='3-9-2原材料'!J26 -> 4000 | E7: =D7-C7 -> 4000 | F7: =IF(C7=0,"",E7/C7*100)
A8: 3-9-3 | B8: 在库周转材料 | C8: 0 | D8: 0 | E8: =D8-C8 -> 0 | F8: =IF(C8=0,"",E8/C8*100)
A9: 3-9-4 | B9: 委托加工物资 | C9: 0 | D9: 0 | E9: =D9-C9 -> 0 | F9: =IF(C9=0,"",E9/C9*100)
A10: 3-9-5 | B10: 产成品（库存商品） | C10: 0 | D10: 0 | E10: =D10-C10 -> 0 | F10: =IF(C10=0,"",E10/C10*100)
A11: 3-9-6 | B11: 在产品（自制半成品） | C11: 0 | D11: 0 | E11: =D11-C11 -> 0 | F11: =IF(C11=0,"",E11/C11*100)
A12: 3-9-7 | B12: 发出商品 | C12: 0 | D12: 0 | E12: =D12-C12 -> 0 | F12: =IF(C12=0,"",E12/C12*100)
A13: 3-9-8 | B13: 在用周转材料 | C13: 0 | D13: 0 | E13: =D13-C13 -> 0 | F13: =IF(C13=0,"",E13/C13*100)
E14: =D14-C14 -> 0 | F14: =IF(C14=0,"",E14/C14*100)
E15: =D15-C15 -> 0 | F15: =IF(C15=0,"",E15/C15*100)
E16: =D16-C16 -> 0 | F16: =IF(C16=0,"",E16/C16*100)
E17: =D17-C17 -> 0 | F17: =IF(C17=0,"",E17/C17*100)
E18: =D18-C18 -> 0 | F18: =IF(C18=0,"",E18/C18*100)
E19: =D19-C19 -> 0 | F19: =IF(C19=0,"",E19/C19*100)
E21: =D21-C21 -> 0 | F21: =IF(C21=0,"",E21/C21*100)
E22: =D22-C22 -> 0 | F22: =IF(C22=0,"",E22/C22*100)
E23: =D23-C23 -> 0 | F23: =IF(C23=0,"",E23/C23*100)
A24: 合 计 | C24: =SUM(C6:C23) -> 0 | D24: =SUM(D6:D23) -> 4000 | E24: =D24-C24 -> 4000 | F24: =IF(C24=0,"",E24/C24*100)
A25: 减：存货跌价准备 | E25: =D25-C25 -> 0 | F25: =IF(C25=0,"",E25/C25*100)
A26: 合 计 | C26: =C24-C25 -> 0 | D26: =D24-D25 -> 4000 | E26: =D26-C26 -> 4000 | F26: =IF(C26=0,"",E26/C26*100)
E28: 评估人员：王冰、武亚斌

Sheet 3-9-2原材料
A1: 存货—原材料评估明细表
A2: ='3-9存货汇总'!A2 -> 评估基准日：2018年10月23日
M3: 表3-9-2
A4: ='3-9存货汇总'!A4 -> 被执行人：俞海敏 | M4: 金额单位：人民币元
H5: 1 | I5: 1 | J5: 1 | K5: 1 | L5: 1
A6: 序号 | B6: 名称及规格型号 | C6: 计量单位 | D6: 存放地点 | E6: 账面价值 | H6: 实际数量 | I6: 评估价值 | K6: 增值额 | L6: 增值率% | M6: 备注
E7: 数量 | F7: 单价 | G7: 金额 | I7: 评估单价 | J7: 金额
A8: 1 | B8: 地砖300mm*600mm | C8: 块 | H8: 176 | I8: 8.38 | J8: =ROUND(H8*I8,-1) -> 1470 | K8: =J8-G8 -> 1470 | L8: =IF(G8=0,"",K8/G8*100)
A9: 2 | B9: 墙砖300mm*600mm | C9: 块 | H9: 196 | I9: 5.56 | J9: =ROUND(H9*I9,-1) -> 1090 | K9: =J9-G9 -> 1090 | L9: =IF(G9=0,"",K9/G9*100)
A10: 3 | B10: 墙砖300mm*300mm | C10: 块 | H10: 180 | I10: 4.94 | J10: =ROUND(H10*I10,-1) -> 890 | K10: =J10-G10 -> 890 | L10: =IF(G10=0,"",K10/G10*100)
A11: 4 | B11: 地砖300mm*300mm | C11: 块 | H11: 91 | I11: 4.96 | J11: =ROUND(H11*I11,-1) -> 450 | K11: =J11-G11 -> 450 | L11: =IF(G11=0,"",K11/G11*100)
A12: 5 | B12: 中财电工套管PVC-U电工套管φ=40mm L=3m | C12: 根 | H12: 2 | I12: 6.54 | J12: =ROUND(H12*I12,-1) -> 10 | K12: =J12-G12 -> 10 | L12: =IF(G12=0,"",K12/G12*100)
A13: 6 | B13: 中财电工套管PVC-U电工套管φ=20mm L=3m | C13: 根 | H13: 37 | I13: 2.51 | J13: =ROUND(H13*I13,-1) -> 90 | K13: =J13-G13 -> 90 | L13: =IF(G13=0,"",K13/G13*100)
K14: =J14-G14 -> 0 | L14: =IF(G14=0,"",K14/G14*100)
K15: =J15-G15 -> 0 | L15: =IF(G15=0,"",K15/G15*100)
K16: =J16-G16 -> 0 | L16: =IF(G16=0,"",K16/G16*100)
K17: =J17-G17 -> 0 | L17: =IF(G17=0,"",K17/G17*100)
K18: =J18-G18 -> 0 | L18: =IF(G18=0,"",K18/G18*100)
K19: =J19-G19 -> 0 | L19: =IF(G19=0,"",K19/G19*100)
K20: =J20-G20 -> 0 | L20: =IF(G20=0,"",K20/G20*100)
K21: =J21-G21 -> 0 | L21: =IF(G21=0,"",K21/G21*100)
K22: =J22-G22 -> 0 | L22: =IF(G22=0,"",K22/G22*100)
K23: =J23-G23 -> 0 | L23: =IF(G23=0,"",K23/G23*100)
K24: =J24-G24 -> 0 | L24: =IF(G24=0,"",K24/G24*100)
K25: =J25-G25 -> 0 | L25: =IF(G25=0,"",K25/G25*100)
A26: 余额合计 | E26: =ROUND(SUM(E8:E25),2) -> 0 | G26: =ROUND(SUM(G8:G25),2) -> 0 | H26: =ROUND(SUM(H8:H25),2) -> 682 | J26: =ROUND(SUM(J8:J25),2) -> 4000 | K26: =J26-G26 -> 4000 | L26: =IF(G26=0,"",K26/G26*100)
A27: 减：存货跌价准备 | E27: =ROUND(SUM(E9:E26),2) -> 0 | G27: =ROUND(SUM(G9:G26),2) -> 0 | K27: =J27-G27 -> 0 | L27: =IF(G27=0,"",K27/G27*100)
A28: 净额合计 | E28: =ROUND(SUM(E10:E27),2) -> 0 | G28: =G26-G27 -> 0 | H28: =ROUND(SUM(H8:H25),2) -> 682 | J28: =J26-J27 -> 4000 | K28: =J28-G28 -> 4000 | L28: =IF(G28=0,"",K28/G28*100)

Sheet 4-非流动资产汇总
A1: 非流动资产评估汇总表
A2: 评估基准日：2018年10月23日
F3: 表4
A4: 被评估单位：俞海敏 | F4: 金额单位：人民币元
A5: 编号 | B5: 科目名称 | C5: 账面价值 | D5: 评估价值 | E5: 增值额 | F5: 增值率%
A6: 4-1 | B6: 可供出售金融资产 | C6: 0 | D6: 0 | E6: =D6-C6 -> 0 | F6: =IF(C6=0,"",E6/C6*100)
A7: 4-2 | B7: 持有至到期投资 | C7: 0 | D7: 0 | E7: =D7-C7 -> 0 | F7: =IF(C7=0,"",E7/C7*100)
A8: 4-3 | B8: 长期应收款 | C8: 0 | D8: 0 | E8: =D8-C8 -> 0 | F8: =IF(C8=0,"",E8/C8*100)
A9: 4-4 | B9: 长期股权投资 | C9: 0 | D9: 0 | E9: =D9-C9 -> 0 | F9: =IF(C9=0,"",E9/C9*100)
A10: 4-5 | B10: 投资性房地产 | C10: 0 | D10: 0 | E10: =D10-C10 -> 0 | F10: =IF(C10=0,"",E10/C10*100)
A11: 4-6 | B11: 固定资产 | C11: ='4-6固定资产汇总'!D33 -> 0 | D11: ='4-6固定资产汇总'!F33 -> 2294400 | E11: =D11-C11 -> 2294400 | F11: =IF(C11=0,"",E11/C11*100)
A12: 4-7 | B12: 在建工程 | C12: 0 | D12: 0 | E12: =D12-C12 -> 0 | F12: =IF(C12=0,"",E12/C12*100)
A13: 4-8 | B13: 工程物资 | C13: 0 | D13: 0 | E13: =D13-C13 -> 0 | F13: =IF(C13=0,"",E13/C13*100)
A14: 4-9 | B14: 固定资产清理 | C14: 0 | D14: 0 | E14: =D14-C14 -> 0 | F14: =IF(C14=0,"",E14/C14*100)
A15: 4-10 | B15: 生产性生物资产 | C15: 0 | D15: 0 | E15: =D15-C15 -> 0 | F15: =IF(C15=0,"",E15/C15*100)
A16: 4-11 | B16: 油气资产 | C16: 0 | D16: 0 | E16: =D16-C16 -> 0 | F16: =IF(C16=0,"",E16/C16*100)
A17: 4-12 | B17: 无形资产 | C17: 0 | D17: 0 | E17: =D17-C17 -> 0 | F17: =IF(C17=0,"",E17/C17*100)
A18: 4-13 | B18: 开发支出 | C18: 0 | D18: 0 | E18: =D18-C18 -> 0 | F18: =IF(C18=0,"",E18/C18*100)
A19: 4-14 | B19: 商誉 | C19: 0 | D19: 0 | E19: =D19-C19 -> 0 | F19: =IF(C19=0,"",E19/C19*100)
A20: 4-15 | B20: 长期待摊费用 | C20: 0 | D20: 0 | E20: =D20-C20 -> 0 | F20: =IF(C20=0,"",E20/C20*100)
A21: 4-16 | B21: 递延所得税资产 | C21: 0 | D21: 0 | E21: =D21-C21 -> 0 | F21: =IF(C21=0,"",E21/C21*100)
A22: 4-17 | B22: 其他非流动资产 | C22: 0 | D22: 0 | E22: =D22-C22 -> 0 | F22: =IF(C22=0,"",E22/C22*100)
F23: =IF(C23=0,"",E23/C23*100)
F24: =IF(C24=0,"",E24/C24*100)
F25: =IF(C25=0,"",E25/C25*100)
A26: 合 计 | C26: =SUM(C6:C25) -> 0 | D26: =SUM(D6:D25) -> 2294400 | E26: =D26-C26 -> 2294400 | F26: =IF(C26=0,"",E26/C26*100)
E28: 评估人员：

Sheet 4-6固定资产汇总
A1: 固定资产评估汇总表
A2: ='1-汇总表'!A2 -> 评估基准日：2018年10月23日
F3: 表4-6 | J3: 表4-6
A4: 被执行人（被评估单位）：俞海敏 | F4: 金额单位：人民币元 | J4: 金额单位：人民币元
A5: 编号 | B5: 科目名称 | C5: 账面价值 | E5: 评估价值 | G5: 增值额 | I5: 增值率%
C6: 原值 | D6: 净值 | E6: 原值 | F6: 净值 | G6: 原值 | H6: 净值 | I6: 原值 | J6: 净值
B7: 房屋建筑物类合计 | C7: =SUM(C8:C10) -> 0 | D7: =SUM(D8:D10) -> 0 | E7: =SUM(E8:E10) -> 0 | F7: =SUM(F8:F10) -> 2294400 | G7: =E7-C7 -> 0 | H7: =F7-D7 -> 2294400 | I7: =IF(C7=0,"",G7/C7*100) | J7: =IF(D7=0,"",H7/D7*100)
A8: 4-6-1 | B8: 固定资产-房屋建筑物 | C8: ='4-6-1房屋建筑物'!I27 -> 0 | D8: ='4-6-1房屋建筑物'!J27 -> 0 | E8: ='4-6-1房屋建筑物'!K27 -> 0 | F8: ='4-6-1房屋建筑物'!M27 -> 2294400 | G8: =E8-C8 -> 0 | H8: =F8-D8 -> 2294400 | I8: =IF(C8=0,"",G8/C8*100) | J8: =IF(D8=0,"",H8/D8*100)
A9: 4-6-2 | B9: 固定资产-构筑物及其他辅助设施 | C9: 0 | D9: 0 | E9: 0 | F9: 0 | G9: =E9-C9 -> 0 | H9: =F9-D9 -> 0 | I9: =IF(C9=0,"",G9/C9*100) | J9: =IF(D9=0,"",H9/D9*100)
A10: 4-6-3 | B10: 固定资产-管道及沟槽 | C10: 0 | D10: 0 | E10: 0 | F10: 0 | G10: =E10-C10 -> 0 | H10: =F10-D10 -> 0 | I10: =IF(C10=0,"",G10/C10*100) | J10: =IF(D10=0,"",H10/D10*100)
I11: =IF(C11=0,"",G11/C11*100) | J11: =IF(D11=0,"",H11/D11*100)
I12: =IF(C12=0,"",G12/C12*100) | J12: =IF(D12=0,"",H12/D12*100)
B13: 设备类合计 | E13: =SUM(E14:E15) -> 0 | F13: =SUM(F14:F15) -> 0 | I13: =IF(C13=0,"",G13/C13*100) | J13: =IF(D13=0,"",H13/D13*100)
A14: 4-6-4 | B14: 固定资产-机器设备 | E14: 0 | F14: 0 | I14: =IF(C14=0,"",G14/C14*100) | J14: =IF(D14=0,"",H14/D14*100)
A31: 固定资产合计 | E31: =E13 -> 0 | F31: =F7+F13 -> 2294400 | G31: =E31-C31 -> 0 | H31: =F31-D31 -> 2294400 | I31: =IF(C31=0,"",G31/C31*100) | J31: =IF(D31=0,"",H31/D31*100)
A32: 减：固定资产减值准备 | G32: =E32-C32 -> 0 | H32: =F32-D32 -> 0 | I32: =IF(C32=0,"",G32/C32*100) | J32: =IF(D32=0,"",H32/D32*100)
A33: 固定资产合计 | E33: =E31-E32 -> 0 | F33: =F31-F32 -> 2294400 | G33: =E33-C33 -> 0 | H33: =F33-D33 -> 2294400 | I33: =IF(C33=0,"",G33/C33*100) | J33: =IF(D33=0,"",H33/D33*100)
E35: 评估人员：王冰、武亚斌

Sheet 4-6-1房屋建筑物
A1: 固定资产—房屋建筑物评估明细表
A2: ='1-汇总表'!A2 -> 评估基准日：2018年10月23日
R3: 表4-6-1
A4: ='1-汇总表'!A4 -> 被执行人：俞海敏 | R4: 金额单位：人民币元
K5: 1 | L5: 1 | M5: 1 | N5: 1 | O5: 1 | P5: 1 | Q5: 1
A6: 序号 | B6: 权证编号 | C6: 建筑物名称 | D6: 结构 | E6: 建成 年月 | F6: 计量单位 | G6: 建筑面积(m2) | H6: 土地使用权面积(m2) | I6: 账面价值 | K6: 评估价值 | M6: 评估价值 | N6: 增值额 | P6: 增值率% | Q6: 评估单价(元/m2) | R6: 备注
I7: 原值 | J7: 净值 | K7: 原值 | L7: 成新率% | N7: 原值 | O7: 净值
A8: 1 | B8: 浙（2017）余杭区不动产权第0062699号 | C8: 余杭区仁和街道清合嘉园西区34幢3单元202室 | D8: 钢混 | E8: 2005年 | F8: ㎡ | G8: 208.58 | H8: 109.1 | M8: =ROUND(Q8*G8,-2) -> 2294400 | N8: =K8-I8 -> 0 | O8: =M8-J8 -> 2294400 | P8: =IF(J8=0,"",O8/J8*100) | Q8: 11000
N9: =K9-I9 -> 0 | O9: =M9-J9 -> 0 | P9: =IF(J9=0,"",O9/J9*100) | Q9: =IF(G9=0,"",ROUND(K9/G9,0))
N10: =K10-I10 -> 0 | O10: =M10-J10 -> 0 | P10: =IF(J10=0,"",O10/J10*100) | Q10: =IF(G10=0,"",ROUND(K10/G10,0))
N11: =K11-I11 -> 0 | O11: =M11-J11 -> 0 | P11: =IF(J11=0,"",O11/J11*100) | Q11: =IF(G11=0,"",ROUND(K11/G11,0))
N12: =K12-I12 -> 0 | O12: =M12-J12 -> 0 | P12: =IF(J12=0,"",O12/J12*100) | Q12: =IF(G12=0,"",ROUND(K12/G12,0))
N13: =K13-I13 -> 0 | O13: =M13-J13 -> 0 | P13: =IF(J13=0,"",O13/J13*100) | Q13: =IF(G13=0,"",ROUND(K13/G13,0))
N14: =K14-I14 -> 0 | O14: =M14-J14 -> 0 | P14: =IF(J14=0,"",O14/J14*100) | Q14: =IF(G14=0,"",ROUND(K14/G14,0))
N15: =K15-I15 -> 0 | O15: =M15-J15 -> 0 | P15: =IF(J15=0,"",O15/J15*100) | Q15: =IF(G15=0,"",ROUND(K15/G15,0))
N16: =K16-I16 -> 0 | O16: =M16-J16 -> 0 | P16: =IF(J16=0,"",O16/J16*100) | Q16: =IF(G16=0,"",ROUND(K16/G16,0))
N17: =K17-I17 -> 0 | O17: =M17-J17 -> 0 | P17: =IF(J17=0,"",O17/J17*100) | Q17: =IF(G17=0,"",ROUND(K17/G17,0))
N18: =K18-I18 -> 0 | O18: =M18-J18 -> 0 | P18: =IF(J18=0,"",O18/J18*100) | Q18: =IF(G18=0,"",ROUND(K18/G18,0))
N19: =K19-I19 -> 0 | O19: =M19-J19 -> 0 | P19: =IF(J19=0,"",O19/J19*100) | Q19: =IF(G19=0,"",ROUND(K19/G19,0))
N20: =K20-I20 -> 0 | O20: =M20-J20 -> 0 | P20: =IF(J20=0,"",O20/J20*100) | Q20: =IF(G20=0,"",ROUND(K20/G20,0))
N21: =K21-I21 -> 0 | O21: =M21-J21 -> 0 | P21: =IF(J21=0,"",O21/J21*100) | Q21: =IF(G21=0,"",ROUND(K21/G21,0))
O22: =M22-J22 -> 0 | P22: =IF(J22=0,"",O22/J22*100)
O23: =M23-J23 -> 0 | P23: =IF(J23=0,"",O23/J23*100)
N24: =K24-I24 -> 0 | O24: =M24-J24 -> 0 | P24: =IF(J24=0,"",O24/J24*100) | Q24: =IF(G24=0,"",ROUND(K24/G24,0))
N25: =K25-I25 -> 0 | O25: =M25-J25 -> 0 | P25: =IF(J25=0,"",O25/J25*100) | Q25: =IF(G25=0,"",ROUND(K25/G25,0))
N26: =K26-I26 -> 0 | O26: =M26-J26 -> 0 | P26: =IF(J26=0,"",O26/J26*100) | Q26: =IF(G26=0,"",ROUND(K26/G26,0))
A27: 合 计 | I27: =ROUND(SUM(I8:I26),2) -> 0 | J27: =ROUND(SUM(J8:J26),2) -> 0 | K27: =ROUND(SUM(K8:K26),2) -> 0 | M27: =ROUND(SUM(M8:M26),2) -> 2294400 | N27: =K27-I27 -> 0 | O27: =M27-J27 -> 2294400 | P27: =IF(J27=0,"",O27/J27*100)
A28: 减：房屋建筑物减值准备 | N28: =K28-I28 -> 0 | O28: =M28-J28 -> 0 | P28: =IF(J28=0,"",O28/J28*100)
A29: 合 计 | I29: =I27-I28 -> 0 | J29: =J27-J28 -> 0 | K29: =K27-K28 -> 0 | M29: =M27-M28 -> 2294400 | N29: =K29-I29 -> 0 | O29: =M29-J29 -> 2294400 | P29: =IF(J29=0,"",O29/J29*100)
